<?xml version="1.0"?>
<robot  xmlns:sensor="http://playerstage.sourceforge.net/gazebo/xmlschema/#sensor"
        xmlns:controller="http://playerstage.sourceforge.net/gazebo/xmlschema/#controller"
        xmlns:interface="http://playerstage.sourceforge.net/gazebo/xmlschema/#interface"
        xmlns:xacro="http://ros.org/wiki/xacro">

  <!-- sensors -->
  <xacro:include filename="$(find talos_description)/urdf/sensors/sick_tim561_laser.urdf.xacro"/>

  <xacro:include filename="$(find talos_description)/urdf/talos_base/base.gazebo.xacro" />
  <xacro:include filename="$(find talos_description)/urdf/talos_base/base.transmission.xacro" />

  <xacro:property name="M_PI" value="3.141592" />

  <!-- simplified box collision geometry for base -->
  <xacro:property name="base_mass" value="15.0" />

  <xacro:property name="caster_mass" value="0.1" />

  <xacro:property name="wheel_offset_x" value="0.0"  />  
  <xacro:property name="wheel_offset_y" value="0.0"  />  
  <xacro:property name="wheel_offset_z" value="0.0" />
  <xacro:property name="wheel_mass" value="0.4" />

  <xacro:property name="wheel_radius" value="0.05" />

  <xacro:property name="wheel_joint_damping" value="1.0" />
  <xacro:property name="wheel_joint_friction" value="1.0" />
  <xacro:property name="wheel_joint_effort" value="30" />
  <xacro:property name="wheel_joint_velocity" value="10" />
  <xacro:property name="wheel_joint_safety_k_velocity" value="10.0" />

  <xacro:macro name = "talos_base" params="name">

    <link name="${name}_footprint"/>

    <joint name="${name}_footprint_joint" type="fixed">
      <origin xyz="0 0 0" rpy="0 0 0" />
      <child link="${name}_link" />
      <parent link="${name}_footprint"/>
    </joint>

    <link name="${name}_link">
      <inertial>
        <mass value="${base_mass}" />
        <origin xyz="0 0 0" />
        <inertia ixx="5.652232699207" ixy="-0.009719934438" ixz="1.293988226423" iyy="5.669473158652" iyz="-0.007379583694" izz="3.683196351726" />
      </inertial>
      <visual>
        <origin xyz="0 0 0" rpy="0 0 0" />  
        <geometry>
          <mesh filename="package://talos_description/meshes/talos_base/talos_base.stl"/>
        </geometry> 
      </visual>
      <collision>
        <origin xyz="0 0 0" rpy="0 0 0" />
        <geometry>
          <!--<box size="${base_size_x} ${base_size_y} ${base_size_z}" />-->
          <mesh filename="package://talos_description/meshes/talos_base/talos_base.stl"/>
        </geometry>
      </collision>
    </link>		

    <!-- front left omni-wheel -->		
    <joint name="caster_joint_fl" type="fixed">
      <origin xyz="0.118 0.217 0.038" rpy="0 0 -2.0944" />
      <axis xyz="0 0 1" />
      <parent link="${name}_link"/>
      <child link="caster_link_fl" />
    </joint>

    <link name="caster_link_fl">
      <inertial>
        <mass value="${caster_mass}" />
        <origin xyz="0 0 0" />
        <inertia  ixx="0.012411765597" ixy="-0.000711733678" ixz="0.00050272983" iyy="0.015218160428" iyz="-0.000004273467" izz="0.011763977943" />
      </inertial>
    </link>

    <joint name="wheel_joint_fl" type="continuous">
      <axis xyz="0 1 0" />
      <limit effort="${wheel_joint_effort}" velocity="${wheel_joint_velocity}"/> 
      <origin xyz="${wheel_offset_x} ${wheel_offset_y} ${wheel_offset_z}" rpy="0 0 0" />
      <parent link="caster_link_fl"/>
      <dynamics damping="${wheel_joint_damping}" friction="${wheel_joint_friction}" />
      <safety_controller k_velocity="${wheel_joint_safety_k_velocity}" />
      <child link="wheel_link_fl"/>
    </joint>

    <link name="wheel_link_fl">
      <inertial>
        <mass value="${wheel_mass}" />
        <origin xyz="0 0 0" />
        <inertia  ixx="0.012411765597" ixy="-0.000711733678" ixz="0.00050272983" iyy="0.015218160428" iyz="-0.000004273467" izz="0.011763977943" />
      </inertial>
      <visual>
        <origin xyz="0 0 0" rpy="0 0 0" />
        <geometry>
          <mesh filename="package://talos_description/meshes/talos_base/omniwheel.stl" />
        </geometry>
      </visual>
      <collision>
        <origin xyz="0 0 0" rpy="${M_PI/2} 0 0" />
        <geometry>
          <cylinder radius="${wheel_radius}" length="${wheel_radius}" />
        </geometry>
      </collision>
    </link>


    <!-- front right omni-wheel -->
    <joint name="caster_joint_fr" type="fixed">
      <origin xyz="0.118 -0.211 0.038" rpy="0 ${M_PI} -1.0472" />
      <axis xyz="0 0 1" />
      <parent link="${name}_link"/>
      <child link="caster_link_fr" />
    </joint>

    <link name="caster_link_fr">
      <inertial>
        <mass value="${caster_mass}" />
        <origin xyz="0 0 0" />
        <inertia  ixx="0.012411765597" ixy="-0.000711733678" ixz="0.00050272983" iyy="0.015218160428" iyz="-0.000004273467" izz="0.011763977943" />
      </inertial>
    </link>

    <joint name="wheel_joint_fr" type="continuous">
      <axis xyz="0 1 0" />
      <limit effort="${wheel_joint_effort}" velocity="${wheel_joint_velocity}"/> 
      <dynamics damping="${wheel_joint_damping}" friction="${wheel_joint_friction}" />
      <safety_controller k_velocity="${wheel_joint_safety_k_velocity}" />
      <origin xyz="${wheel_offset_x} ${wheel_offset_y} ${wheel_offset_z}" rpy="0 0 0" />
      <parent link="caster_link_fr"/>
      <child link="wheel_link_fr"/>
    </joint>

    <link name="wheel_link_fr">
      <inertial>
        <mass value="${wheel_mass}" />
        <origin xyz="0 0 0" />
        <inertia  ixx="0.012411765597" ixy="-0.000711733678" ixz="0.00050272983" iyy="0.015218160428" iyz="-0.000004273467" izz="0.011763977943" />
      </inertial>
      <visual>
        <origin xyz="0 0 0" rpy="0 0 0" />
        <geometry>
          <mesh filename="package://talos_description/meshes/talos_base/omniwheel.stl" />
        </geometry>
      </visual>
      <collision>
        <origin xyz="0 0 0" rpy="${M_PI/2} 0 0" />
        <geometry>
          <cylinder radius="${wheel_radius}" length="${wheel_radius}" />
        </geometry>
      </collision>
    </link>

    <!-- back omni-wheel -->
    <joint name="caster_joint_b" type="fixed">
      <origin xyz="-0.253 0 0.038" rpy="0 0 0" />
      <axis xyz="0 0 1" />
      <parent link="${name}_link"/>
      <child link="caster_link_b" />
    </joint>

    <link name="caster_link_b">
      <inertial>
        <mass value="${caster_mass}" />
        <origin xyz="0 0 0" />
        <inertia  ixx="0.012411765597" ixy="-0.000711733678" ixz="0.00050272983" iyy="0.015218160428" iyz="-0.000004273467" izz="0.011763977943" />
      </inertial>
    </link>

    <joint name="wheel_joint_b" type="continuous">
      <axis xyz="0 1 0" />
      <limit effort="10" velocity="10"/> 
      <limit effort="${wheel_joint_effort}" velocity="${wheel_joint_velocity}"/>             		
      <dynamics damping="${wheel_joint_damping}" friction="${wheel_joint_friction}" />
      <safety_controller k_velocity="${wheel_joint_safety_k_velocity}" />
      <origin xyz="${wheel_offset_x} ${wheel_offset_y} ${wheel_offset_z}" rpy="0 0 0" />
      <parent link="caster_link_b"/>
      <child link="wheel_link_b"/>
    </joint>

    <link name="wheel_link_b">
      <inertial>
        <mass value="${wheel_mass}" />
        <origin xyz="0 0 0" />
        <inertia  ixx="0.012411765597" ixy="-0.000711733678" ixz="0.00050272983" iyy="0.015218160428" iyz="-0.000004273467" izz="0.011763977943" />
      </inertial>
      <visual>
        <origin xyz="0 0 0" rpy="0 0 0" />
        <geometry>
          <mesh filename="package://talos_description/meshes/talos_base/omniwheel.stl" />
        </geometry>
      </visual>
      <collision>
        <origin xyz="0 0 0" rpy="${M_PI/2} 0 0" />
        <geometry>
          <cylinder radius="${wheel_radius}" length="${wheel_radius}" />
        </geometry>
      </collision>
    </link>

    <!-- base laser front left-->

    <xacro:sick_tim561_laser name="${name}_laser_left" parent="${name}" ros_topic="scan_left" update_rate="15" min_angle="-2.2" max_angle="2.5" >
      <origin xyz="0.153 0.279 0.03" rpy="0 0 1.0821" />
    </xacro:sick_tim561_laser>

    <!-- base laser front right-->

    <xacro:sick_tim561_laser name="${name}_laser_right" parent="${name}" ros_topic="scan_right" update_rate="15" min_angle="-2.5" max_angle="2.2" >
      <origin xyz="0.153 -0.27 0.03" rpy="0 0 -1.0821" />
    </xacro:sick_tim561_laser>

    <!-- extensions -->
    <xacro:talos_base_gazebo />
    <xacro:talos_base_transmission />


  </xacro:macro>


</robot>
