<?xml version="1.0"?>
<robot  xmlns:sensor="http://playerstage.sourceforge.net/gazebo/xmlschema/#sensor"
        xmlns:controller="http://playerstage.sourceforge.net/gazebo/xmlschema/#controller"
        xmlns:interface="http://playerstage.sourceforge.net/gazebo/xmlschema/#interface"
        xmlns:xacro="http://ros.org/wiki/xacro">

	<xacro:include filename="$(find talos_description)/urdf/talos_arm/arm.gazebo.xacro" />
	<xacro:include filename="$(find talos_description)/urdf/talos_arm/arm.transmission.xacro" />
    <xacro:include filename="$(find talos_description)/urdf/talos_arm/limits.urdf.xacro" />
	<xacro:include filename="$(find realsense2_description)/urdf/_d435.urdf.xacro"/>


	<xacro:macro name="talos_arm" params="parent name *origin">

		<xacro:sensor_d435 name="camera" topics_ns="camera" parent="${name}_link_4" publish_pointcloud="true">
			<origin xyz="0.025 0.0 0.01" rpy="0 0 0" />
		</xacro:sensor_d435>


		<!-- joint between base_link and arm_0_link -->
		<joint name="${name}_joint_0" type="revolute" >
			<xacro:insert_block name="origin" />
			<parent link="${parent}" />
			<child link="${name}_link_0" />
			<axis xyz="0 0 1"/>
			<dynamics damping="10" friction="5" />
			<limit effort="100" velocity="${M_PI / 2.0}" lower="-${joint_0_limit}" upper="${joint_0_limit}"/>
		</joint>

		<link name="${name}_link_0">
			<inertial>
				<!--<origin xyz="0.023 0 0.006" rpy="0 0 0"/>-->
				<origin xyz="0 0 0" rpy="0 0 0"/>
				<mass value="${link_0_mass}"/>
				<inertia ixx="0.01" ixy="0" ixz="0" iyy="0.01" iyz="0" izz="0.01" />
			</inertial>
			<visual>
				<origin xyz="0 0 0" rpy="0 0 0" />
				<geometry>
					<mesh filename="package://talos_description/meshes/talos_arm/shoulder_link.stl" />
				</geometry>
				<xacro:material_Black />
			</visual>
			<collision>
				<!--<origin xyz="0.023 0 0.006" rpy="0 0 0"/>-->
				<origin xyz="0 0 0" rpy="0 0 0"/>
				<geometry>
					<mesh filename="package://talos_description/meshes/talos_arm/shoulder_link.stl" />
					<!--<cylinder length="0.078" radius="0.093"/>-->
				</geometry>
			</collision>			
			
		</link>

		<!-- joint between arm_0_link and arm_1_link -->
		<joint name="${name}_joint_1" type="revolute">
			<origin xyz="0 0 0" rpy="0 0 0"/>
			<parent link="${name}_link_0"/>
			<child link="${name}_link_1"/>
			<axis xyz="0 1 0"/>
			<!--<calibration rising="${arm_1_ref}" falling="${arm_1_ref}"/>-->
			<dynamics damping="10" friction="5" />
			<!-- damping - N*s/m, N*s*m/rad -->
			<!-- friction - N, N*m -->			
			<limit effort="100" velocity="${M_PI / 2.0}" lower="-${joint_1_limit}" upper="${joint_1_limit}"/> 
			<!--effort - N, N*m-->
			<!--velocity - m/s, rad/s-->
			<!--k_position N/m, N/rad-->
			<!--k_velocity N*s/m, N*s*m/rad-->
			<!--for details: http://www.ros.org/wiki/pr2_controller_manager/safety_limits-->
		</joint>

		<link name="${name}_link_1">
			<inertial>
				<mass value="${link_1_mass}"/>
				<xacro:link_1_inertia_tensor />
			</inertial>
			<visual>
				<origin xyz="0.0482 0 0.14" rpy="0 0 0" />
				<geometry>
					<mesh filename="package://talos_description/meshes/talos_arm/biceps_link.stl" />
				</geometry>
				<xacro:material_Black />
			</visual>
			<collision>
				<!--<origin xyz="0 0 -0.003" rpy="0 0 0" />-->
				<origin xyz="0.0482 0 0.14" rpy="0 0 0" />
				<geometry>
					<mesh filename="package://talos_description/meshes/talos_arm/biceps_link.stl" />
					<!--<cylinder length="0.102" radius="0.080"/>-->
				</geometry>
			</collision>		
		</link>

		<!-- joint between arm_1_link and arm_2_link -->	
		<joint name="${name}_joint_2" type="revolute">
			<origin xyz="0.0482 0 0.142" rpy="0 ${M_PI / 2} 0"/>
			<parent link="${name}_link_1"/>
			<child link="${name}_link_2"/>
			<axis xyz="0 1 0"/>
			<!--<calibration rising="${arm_2_ref}" falling="${arm_2_ref}"/>-->
			<dynamics damping="10" friction="5" />
			<limit effort="100" velocity="${M_PI / 2.0}" lower="-${joint_2_limit}" upper="${joint_2_limit}"/>
		</joint>

		<link name="${name}_link_2">
			<inertial>
				<mass value="${link_2_mass}"/>
				<xacro:link_2_inertia_tensor />
			</inertial>
			<visual>
			<origin xyz="0 0 0.142" rpy="0 0 0" />
				<geometry>
					<mesh filename="package://talos_description/meshes/talos_arm/forearm_link.stl" />
				</geometry>
				<xacro:material_Black />
			</visual>
			<collision>
				<!--<origin xyz="0.001 -0.041 0.074" rpy="0 0 0" />-->
				<origin xyz="0 0 0.142" rpy="0 0 0" />
				<geometry>
					<mesh filename="package://talos_description/meshes/talos_arm/forearm_link.stl" />
					<!--<box size="0.074 0.082 0.222"/>-->
				</geometry>
			</collision>
		</link>

		<!-- joint between arm_2_link and arm_3_link -->	
		<joint name="${name}_joint_3" type="revolute">
			<origin xyz="0 0 0.142" rpy="0 0 0"/>
			<parent link="${name}_link_2"/>
			<child link="${name}_link_3"/>
			<axis xyz="0 1 0"/>
			<dynamics damping="10" friction="5" />
			<limit effort="100" velocity="${M_PI / 2.0}" lower="-${joint_3_limit}" upper="${joint_3_limit}"/>
		</joint>

		<link name="${name}_link_3">
			<inertial>
				<mass value="${link_3_mass}"/>
				<xacro:link_3_inertia_tensor />
			</inertial>
			<visual>
				<origin xyz="0 0 0" rpy="0 0 0" />
				<geometry>
					<mesh filename="package://talos_description/meshes/talos_arm/wrist_1_link.stl" />
				</geometry>
				<xacro:material_Black />
			</visual>
			<collision>
				<!--<origin xyz="0.000 0.025 0.067" rpy="0 0 0" />-->
				<origin xyz="0 0 0" rpy="0 0 0" />
				<geometry>
					<mesh filename="package://talos_description/meshes/talos_arm/wrist_1_link.stl" />
					<!--<box size="0.064 0.054 0.192"/>-->
				</geometry>
			</collision>
		</link>	

		<!-- joint between arm_3_link and arm_4_link -->
		<joint name="${name}_joint_4" type="revolute">
			<origin xyz="0 0 0.0715" rpy="0 0 0" />
			<parent link="${name}_link_3"/>
			<child link="${name}_link_4"/>
			<axis xyz="0 0 1" />
			<!--<calibration rising="${arm_4_ref}" falling="${arm_4_ref}"/>-->
			<dynamics damping="10" friction="5" />
			<limit effort="100" velocity="${M_PI / 2.0}" lower="-${joint_4_limit}" upper="${joint_4_limit}"/>
		</joint>

		<link name="${name}_link_4">
			<inertial>
				<mass value="${link_4_mass}"/>
				<xacro:link_4_inertia_tensor />
			</inertial>	
			<visual>
				<origin xyz="0 0 0.043" rpy="0 0 0"/>
				<geometry>
					<mesh filename="package://talos_description/meshes/talos_arm/wrist_2_link.stl" />
				</geometry>
				<xacro:material_Black />
			</visual>
			<collision>
				<!--<origin xyz="0 0 0.026" rpy="0 0 0" />-->
				<origin xyz="0 0 0.043" rpy="0 0 0"/>
				<geometry>
					<mesh filename="package://talos_description/meshes/talos_arm/wrist_2_link.stl" />
					<!--<box size="0.058 0.100 0.118"/>-->
				</geometry>
			</collision>
		</link>

		<!-- joint between arm_4_link and arm_5_link -->
		<joint name="${name}_joint_5" type="fixed">
			<origin xyz="0 0 0.043" rpy="0 0 0" />
			<parent link="${name}_link_4"/>
			<child link="${name}_link_5"/>
			<axis xyz="0 0 1" />
			<!--<calibration rising="${arm_4_ref}" falling="${arm_4_ref}"/>-->
			<dynamics damping="10" friction="5" />
			<limit effort="100" velocity="${M_PI / 2.0}" lower="-${joint_5_limit}" upper="${joint_5_limit}"/>
		</joint>

		<link name="${name}_link_5">
			<inertial>
				<mass value="${link_5_mass}"/>
				<xacro:link_5_inertia_tensor />
			</inertial>
			<visual>
				<origin xyz="0 0 0" rpy="0 0 1.57"/>
				<geometry>
					<mesh filename="package://talos_description/meshes/talos_arm/gripper_rail_link.stl" />
				</geometry>
				<xacro:material_Black />
			</visual>
			<collision>
				<!--<origin xyz="0 0 0.026" rpy="0 0 0" />-->
				<origin xyz="0 0 0" rpy="0 0 1.57"/>
				<geometry>
					<mesh filename="package://talos_description/meshes/talos_arm/gripper_rail_link.stl" />
					<!--<box size="0.058 0.100 0.118"/>-->
				</geometry>
			</collision>
		</link>

		<!-- joint between arm_5_link and arm_6_link -->
		<joint name="${name}_joint_6" type="prismatic">
			<origin xyz="0 0 0" rpy="0 0 0" />
			<parent link="${name}_link_5"/>
			<child link="${name}_link_6"/>
			<axis xyz="0 -1 0" />
			<!--<calibration rising="${arm_5_ref}" falling="${arm_5_ref}"/>-->
			<dynamics damping="1000"/>
			<limit effort="10000" velocity="0.5" lower="0" upper="${joint_6_limit}" />

		</joint>

		<link name="${name}_link_6">
			<inertial>
				<mass value="${link_6_mass}"/>
				<xacro:link_6_inertia_tensor />
			</inertial>
			
			<visual>
				<origin xyz="0 0 0" rpy="0 0 1.57" />
				<geometry>
					<mesh filename="package://talos_description/meshes/talos_arm/gripper_hand_fixed_link.stl" />
				</geometry>
				<xacro:material_Black />
			</visual>
			
			<collision>
				<origin xyz="0 0 0" rpy="0 0 1.57" />
				<geometry>
					<mesh filename="package://talos_description/meshes/talos_arm/gripper_hand_fixed_link.stl" />
					<!--<box size="0.054 0.096 0.030"/>-->
				</geometry>
			</collision>
		</link>

		<!-- joint between arm_5_link and arm_7_link -->
		<joint name="${name}_joint_7" type="prismatic">
			<origin xyz="0 0 0" rpy="0 0 0" />
			<parent link="${name}_link_5"/>
			<child link="${name}_link_7"/>
			<axis xyz="0 1 0" />
			<dynamics damping="1000"/>
			<!--<calibration rising="${arm_5_ref}" falling="${arm_5_ref}"/>-->
			<limit effort="10000" velocity="0.5" lower="0" upper="${joint_7_limit}" />
		</joint>

		<link name="${name}_link_7">
			<inertial>
				<mass value="${link_7_mass}"/>
				<xacro:link_7_inertia_tensor />
			</inertial>
			<visual>
				<origin xyz="0 0 0" rpy="0 0 -1.57" />
				<geometry>
					<mesh filename="package://talos_description/meshes/talos_arm/gripper_hand_fixed_link.stl" />
				</geometry>
				<xacro:material_Black />
			</visual>
			
			<collision>
				<origin xyz="0 0 0" rpy="0 0 -1.57" />
				<geometry>
					<mesh filename="package://talos_description/meshes/talos_arm/gripper_hand_fixed_link.stl" />
					<!--<box size="0.054 0.096 0.030"/>-->
				</geometry>
			</collision>
		</link>

		<!-- extensions -->
		<xacro:talos_arm_gazebo name="${name}" />
		<xacro:talos_arm_transmission name="${name}" />

	</xacro:macro>

</robot>