<?xml version="1.0" ?>
<!-- =================================================================================== -->
<!-- |    This document was autogenerated by xacro from /home/altzi_ts007/talos_sim_ws/src/talos_description/urdf/robots/talos.urdf.xacro | -->
<!-- |    EDITING THIS FILE BY HAND IS NOT RECOMMENDED                                 | -->
<!-- =================================================================================== -->
<robot name="talos" xmlns:controller="http://playerstage.sourceforge.net/gazebo/xmlschema/#controller" xmlns:interface="http://playerstage.sourceforge.net/gazebo/xmlschema/#interface" xmlns:sensor="http://playerstage.sourceforge.net/gazebo/xmlschema/#sensor">
    <!-- The following included files set up definitions of parts of the robot body -->
    <!-- misc common stuff? -->
    <!--include filename="$(find talos_description)/urdf/common.xacro" /-->
    <gazebo reference="talos_base">
        <gravity>true</gravity>
        <selfCollide>true</selfCollide>
        <plugin name="gazebo_ros_control">
            <robotNamespace>/</robotNamespace>
        </plugin>
    </gazebo>
    <!-- front left wheel -->
    <gazebo reference="wheel_link_fl">
        <dampingFactor>100000</dampingFactor>
        <kp>100000.0</kp>
        <kd>1000.0</kd>
        <mu1>0</mu1>
        <mu2>0</mu2>
        <fdir>1 0 0</fdir>
        <maxVel>1.0</maxVel>
        <minDepth>0.0</minDepth>
    </gazebo>
    <gazebo reference="caster_link_fl" />
    <!-- front right wheel -->
    <gazebo reference="wheel_link_fr">
        <dampingFactor>100000</dampingFactor>
        <kp>100000.0</kp>
        <kd>1000.0</kd>
        <mu1>0</mu1>
        <mu2>0</mu2>
        <fdir>1 0 0</fdir>
        <maxVel>1.0</maxVel>
        <minDepth>0.0</minDepth>
    </gazebo>
    <gazebo reference="caster_link_fr" />
    <!-- back left wheel -->
    <gazebo reference="wheel_link_b">
        <dampingFactor>100000</dampingFactor>
        <kp>100000.0</kp>
        <kd>1000.0</kd>
        <mu1>0</mu1>
        <mu2>0</mu2>
        <fdir>1 0 0</fdir>
        <maxVel>1.0</maxVel>
        <minDepth>0.0</minDepth>
    </gazebo>
    <gazebo reference="caster_link_b" />
    &gt;
    <!-- generic simulator_gazebo plugins for starting mechanism control, ros time, ros battery -->
    <!--include filename="$(find talos_description)/gazebo/gazebo.urdf.xacro" /-->
    <!-- Now we can start using the macros included above to define the actual talos -->
    <!-- The first use of a macro.  This one was defined in base.urdf.xacro above.
       A macro like this will expand to a set of link and joint definitions, and to additional
       Gazebo-related extensions (sensor plugins, etc).  The macro takes an argument, name, 
       that equals "base", and uses it to generate names for its component links and joints 
       (e.g., base_link).  The included origin block is also an argument to the macro.  By convention, 
       the origin block defines where the component is w.r.t its parent (in this case the parent 
       is the world frame). For more, see http://www.ros.org/wiki/xacro -->
    <link name="base_link">
        <inertial>
            <mass value="15.0" />
            <origin xyz="0 0 0" rpy="0 0 0" />
            <inertia ixx="5.652232699207" ixy="-0.009719934438" ixz="1.293988226423" iyy="5.669473158652" iyz="-0.007379583694" izz="3.683196351726" />
        </inertial>
        <visual>
            <origin rpy="0 0 0" xyz="0 0 0" />
            <geometry>
                <mesh filename="package://talos_description/meshes/talos_base/talos_base.stl" />
            </geometry>
            <material name="">
                <color rgba="0.3 0.3 0.3 1.0" />
            </material>
        </visual>
        <collision>
            <origin rpy="0 0 0" xyz="0 0 0" />
            <geometry>
                <!--<box size="${base_size_x} ${base_size_y} ${base_size_z}" />-->
                <mesh filename="package://talos_description/meshes/talos_base/talos_base.stl" />
            </geometry>
        </collision>
    </link>
    <!-- front left omni-wheel -->
    <joint name="caster_joint_fl" type="fixed">
        <origin rpy="0 0 -2.0944" xyz="0.118 0.217 0.038" />
        <axis xyz="0 0 1" />
        <parent link="base_link" />
        <child link="caster_link_fl" />
    </joint>
    <link name="caster_link_fl">
        <inertial>
            <mass value="0.1" />
            <origin xyz="0 0 0" />
            <inertia ixx="0.012411765597" ixy="-0.000711733678" ixz="0.00050272983" iyy="0.015218160428" iyz="-0.000004273467" izz="0.011763977943" />
        </inertial>
    </link>
    <joint name="wheel_joint_fl" type="continuous">
        <axis xyz="0 1 0" />
        <limit effort="30" velocity="10" />
        <origin rpy="0 0 0" xyz="0.0 0.0 0.0" />
        <parent link="caster_link_fl" />
        <dynamics damping="1.0" friction="1.0" />
        <safety_controller k_velocity="10.0" />
        <child link="wheel_link_fl" />
    </joint>
    <link name="wheel_link_fl">
        <inertial>
            <mass value="0.4" />
            <origin xyz="0 0 0" rpy="0 0 0" />
            <inertia ixx="0.012411765597" ixy="-0.000711733678" ixz="0.00050272983" iyy="0.015218160428" iyz="-0.000004273467" izz="0.011763977943" />
        </inertial>
        <visual>
            <origin rpy="0 0 0" xyz="0 0 0" />
            <geometry>
                <mesh filename="package://talos_description/meshes/talos_base/omniwheel.stl" />
            </geometry>
            <material name="">
                <color rgba="0.3 0.3 0.3 1.0" />
            </material>
        </visual>
        <collision>
            <origin rpy="1.5707963267948966 0 0" xyz="0 0 0" />
            <geometry>
                <cylinder length="0.05" radius="0.05" />
            </geometry>
        </collision>
    </link>
    <!-- front right omni-wheel -->
    <joint name="caster_joint_fr" type="fixed">
        <origin rpy="0 3.141592653589793 -1.0472" xyz="0.118 -0.211 0.038" />
        <axis xyz="0 0 1" />
        <parent link="base_link" />
        <child link="caster_link_fr" />
    </joint>
    <link name="caster_link_fr">
        <inertial>
            <mass value="0.1" />
            <origin xyz="0 0 0" />
            <inertia ixx="0.012411765597" ixy="-0.000711733678" ixz="0.00050272983" iyy="0.015218160428" iyz="-0.000004273467" izz="0.011763977943" />
        </inertial>
    </link>
    <joint name="wheel_joint_fr" type="continuous">
        <axis xyz="0 1 0" />
        <limit effort="30" velocity="10" />
        <dynamics damping="1.0" friction="1.0" />
        <safety_controller k_velocity="10.0" />
        <origin rpy="0 0 0" xyz="0.0 0.0 0.0" />
        <parent link="caster_link_fr" />
        <child link="wheel_link_fr" />
    </joint>
    <link name="wheel_link_fr">
        <inertial>
            <mass value="0.4" />
            <origin xyz="0 0 0" rpy="0 0 0" />
            <inertia ixx="0.012411765597" ixy="-0.000711733678" ixz="0.00050272983" iyy="0.015218160428" iyz="-0.000004273467" izz="0.011763977943" />
        </inertial>
        <visual>
            <origin rpy="0 0 0" xyz="0 0 0" />
            <geometry>
                <mesh filename="package://talos_description/meshes/talos_base/omniwheel.stl" />
            </geometry>
            <material name="">
                <color rgba="0.3 0.3 0.3 1.0" />
            </material>
        </visual>
        <collision>
            <origin rpy="1.5707963267948966 0 0" xyz="0 0 0" />
            <geometry>
                <cylinder length="0.05" radius="0.05" />
            </geometry>
        </collision>
    </link>
    <!-- back omni-wheel -->
    <joint name="caster_joint_b" type="fixed">
        <origin rpy="0 0 0" xyz="-0.253 0 0.038" />
        <axis xyz="0 0 1" />
        <parent link="base_link" />
        <child link="caster_link_b" />
    </joint>
    <link name="caster_link_b">
        <inertial>
            <mass value="0.1" />
            <origin xyz="0 0 0" />
            <inertia ixx="0.012411765597" ixy="-0.000711733678" ixz="0.00050272983" iyy="0.015218160428" iyz="-0.000004273467" izz="0.011763977943" />
        </inertial>
    </link>
    <joint name="wheel_joint_b" type="continuous">
        <axis xyz="0 1 0" />
        <limit effort="10" velocity="10" />
        <limit effort="30" velocity="10" />
        <dynamics damping="1.0" friction="1.0" />
        <safety_controller k_velocity="10.0" />
        <origin rpy="0 0 0" xyz="0.0 0.0 0.0" />
        <parent link="caster_link_b" />
        <child link="wheel_link_b" />
    </joint>
    <link name="wheel_link_b">
        <inertial>
            <mass value="0.4" />
            <origin xyz="0 0 0" rpy="0 0 0" />
            <inertia ixx="0.012411765597" ixy="-0.000711733678" ixz="0.00050272983" iyy="0.015218160428" iyz="-0.000004273467" izz="0.011763977943" />
        </inertial>
        <visual>
            <origin rpy="0 0 0" xyz="0 0 0" />
            <geometry>
                <mesh filename="package://talos_description/meshes/talos_base/omniwheel.stl" />
            </geometry>
            <material name="">
                <color rgba="0.3 0.3 0.3 1.0" />
            </material>
        </visual>
        <collision>
            <origin rpy="1.5707963267948966 0 0" xyz="0 0 0" />
            <geometry>
                <cylinder length="0.05" radius="0.05" />
            </geometry>
        </collision>
    </link>
    <!-- base laser front left-->
    <joint name="base_laser_left_sick_tim561_laser_joint" type="fixed">
        <axis xyz="0 1 0" />
        <origin rpy="0 0 1.0821" xyz="0.153 0.279 0.03" />
        <parent link="base_link" />
        <child link="base_laser_left_link" />
    </joint>
    <link name="base_laser_left_link" type="laser">
        <inertial>
            <mass value="0.16" />
            <origin rpy="0 0 0" xyz="0 0 0.04" />
            <inertia ixx="0.1" ixy="0" ixz="0" iyy="0.1" iyz="0" izz="0.1" />
        </inertial>
        <visual>
            <origin rpy="0 0 0" xyz="0 0 0.04" />
            <geometry>
                <mesh filename="package://talos_description/meshes/sensors/sick_tim561.stl" />
            </geometry>
            <material name="">
                <color rgba="0.0 0.0 1.0 1.0" />
            </material>
        </visual>
        <collision>
            <origin rpy="0 0 0" xyz="0 0 0.04" />
            <geometry>
                <mesh filename="package://talos_description/meshes/sensors/sick_tim561.stl" />
            </geometry>
        </collision>
    </link>
    <gazebo reference="base_laser_left_link">
        <sensor name="base_laser_left" type="ray">
            <visualize>true</visualize>
            <ray>
                <scan>
                    <horizontal>
                        <samples>811</samples>
                        <resolution>1.0</resolution>
                        <min_angle>-2.2</min_angle>
                        <max_angle>2.5</max_angle>
                    </horizontal>
                </scan>
                <range>
                    <min>0.1</min>
                    <max>5.0</max>
                    <resolution>0.01</resolution>
                </range>
            </ray>
            <plugin filename="libgazebo_ros_laser.so" name="gazebo_ros_base_laser_left_controller">
                <gaussianNoise>0.005</gaussianNoise>
                <alwaysOn>true</alwaysOn>
                <updateRate>15</updateRate>
                <topicName>/scan_L</topicName>
                <frameName>base_laser_left_link</frameName>
            </plugin>
        </sensor>
    </gazebo>
    <!-- base laser front right-->
    <joint name="base_laser_right_sick_tim561_laser_joint" type="fixed">
        <axis xyz="0 1 0" />
        <origin rpy="0 0 -1.0821" xyz="0.153 -0.27 0.03" />
        <parent link="base_link" />
        <child link="base_laser_right_link" />
    </joint>
    <link name="base_laser_right_link" type="laser">
        <inertial>
            <mass value="0.16" />
            <origin rpy="0 0 0" xyz="0 0 0.04" />
            <inertia ixx="0.1" ixy="0" ixz="0" iyy="0.1" iyz="0" izz="0.1" />
        </inertial>
        <visual>
            <origin rpy="0 0 0" xyz="0 0 0.04" />
            <geometry>
                <mesh filename="package://talos_description/meshes/sensors/sick_tim561.stl" />
            </geometry>
            <material name="">
                <color rgba="0.0 0.0 1.0 1.0" />
            </material>
        </visual>
        <collision>
            <origin rpy="0 0 0" xyz="0 0 0.04" />
            <geometry>
                <mesh filename="package://talos_description/meshes/sensors/sick_tim561.stl" />
            </geometry>
        </collision>
    </link>
    <gazebo reference="base_laser_right_link">
        <sensor name="base_laser_right" type="ray">
            <visualize>true</visualize>
            <ray>
                <scan>
                    <horizontal>
                        <samples>811</samples>
                        <resolution>1.0</resolution>
                        <min_angle>-2.5</min_angle>
                        <max_angle>2.2</max_angle>
                    </horizontal>
                </scan>
                <range>
                    <min>0.1</min>
                    <max>5.0</max>
                    <resolution>0.01</resolution>
                </range>
            </ray>
            <plugin filename="libgazebo_ros_laser.so" name="gazebo_ros_base_laser_right_controller">
                <gaussianNoise>0.005</gaussianNoise>
                <alwaysOn>true</alwaysOn>
                <updateRate>15</updateRate>
                <topicName>/scan_R</topicName>
                <frameName>base_laser_right_link</frameName>
            </plugin>
        </sensor>
    </gazebo>
    <gazebo>
        <plugin filename="libgazebo_ros_control.so" name="gazebo_ros_control">
            <robotNamespace>/talos</robotNamespace>
        </plugin>
    </gazebo>
    <gazebo>
        <plugin filename="libgazebo_ros_planar_move.so" name="object_controller">
            <commandTopic>/cmd_vel</commandTopic>
            <odometryTopic>/odom</odometryTopic>
            <odometryFrame>odom</odometryFrame>
            <odometryRate>20.0</odometryRate>
            <robotBaseFrame>base_link</robotBaseFrame>
        </plugin>
    </gazebo>
    <!-- front left omni-wheel -->
    <transmission name="wheel_trans_fl">
        <type>transmission_interface/SimpleTransmission</type>
        <joint name="wheel_joint_fl">
            <hardwareInterface>hardware_interface/VelocityJointInterface</hardwareInterface>
        </joint>
        <actuator name="wheel_motor_fl">
            <hardwareInterface>hardware_interface/VelocityJointInterface</hardwareInterface>
            <mechanicalReduction>79.23809523809524</mechanicalReduction>
        </actuator>
    </transmission>
    <!-- front right omni-wheel -->
    <transmission name="wheel_trans_fr">
        <type>transmission_interface/SimpleTransmission</type>
        <joint name="wheel_joint_fr">
            <hardwareInterface>hardware_interface/VelocityJointInterface</hardwareInterface>
        </joint>
        <actuator name="wheel_motor_fr">
            <hardwareInterface>hardware_interface/VelocityJointInterface</hardwareInterface>
            <mechanicalReduction>79.23809523809524</mechanicalReduction>
        </actuator>
    </transmission>
    <!-- back omni-wheel -->
    <transmission name="wheel_trans_b">
        <type>transmission_interface/SimpleTransmission</type>
        <joint name="wheel_joint_b">
            <hardwareInterface>hardware_interface/VelocityJointInterface</hardwareInterface>
        </joint>
        <actuator name="wheel_motor_b">
            <hardwareInterface>hardware_interface/VelocityJointInterface</hardwareInterface>
            <mechanicalReduction>79.23809523809524</mechanicalReduction>
        </actuator>
    </transmission>
    <material name="camera_aluminum">
        <color rgba="0.5 0.5 0.5 1" />
    </material>
    <!-- camera body, with origin at bottom screw mount -->
    <joint name="camera_joint" type="fixed">
        <origin rpy="0 0 0" xyz="0.025 0.0 0.01" />
        <parent link="arm_link_4" />
        <child link="camera_bottom_screw_frame" />
    </joint>
    <link name="camera_bottom_screw_frame" />
    <joint name="camera_link_joint" type="fixed">
        <origin rpy="0 0 0" xyz="0 0.0175 0.0125" />
        <parent link="camera_bottom_screw_frame" />
        <child link="camera_link" />
    </joint>
    <link name="camera_link">
        <visual>
            <origin rpy="1.5707963267948966 0 1.5707963267948966" xyz="0.0149 -0.0175 0" />
            <geometry>
                <!-- <box size="${d435_cam_width} ${d435_cam_height} ${d435_cam_depth}"/> -->
                <mesh filename="package://realsense2_description/meshes/d435.dae" />
                <!--<mesh filename="package://realsense2_description/meshes/d435/d435.dae" />-->
            </geometry>
            <material name="camera_aluminum" />
        </visual>
        <collision>
            <origin rpy="0 0 0" xyz="0 -0.0175 0" />
            <geometry>
                <box size="0.02505 0.09 0.025" />
            </geometry>
        </collision>
        <!--inertial>
         The following are not reliable values, and should not be used for modeling 
        <mass value="0.564" />
        <origin xyz="0 0 0" />
        <inertia ixx="0.003881243" ixy="0.0" ixz="0.0" iyy="0.000498940" iyz="0.0" izz="0.003879257" />
      </inertial>-->
        <inertial>
            <mass value="0.1" />
            <origin xyz="0 0 0" rpy="0 0 0" />
            <inertia ixx="0.03" iyy="0.03" izz="0.03" ixy="0.0" ixz="0.0" iyz="0.0" />
        </inertial>
    </link>
    <!-- camera depth joints and links -->
    <joint name="camera_depth_joint" type="fixed">
        <origin rpy="0 0 0" xyz="0 0 0" />
        <parent link="camera_link" />
        <child link="camera_depth_frame" />
    </joint>
    <link name="camera_depth_frame" />
    <joint name="camera_depth_optical_joint" type="fixed">
        <origin rpy="-1.5707963267948966 0 -1.5707963267948966" xyz="0 0 0" />
        <parent link="camera_depth_frame" />
        <child link="camera_depth_optical_frame" />
    </joint>
    <link name="camera_depth_optical_frame" />
    <!-- camera left IR joints and links -->
    <joint name="camera_left_ir_joint" type="fixed">
        <origin rpy="0 0 0" xyz="0 0.0 0" />
        <parent link="camera_depth_frame" />
        <child link="camera_left_ir_frame" />
    </joint>
    <link name="camera_left_ir_frame" />
    <joint name="camera_left_ir_optical_joint" type="fixed">
        <origin rpy="-1.5707963267948966 0 -1.5707963267948966" xyz="0 0 0" />
        <parent link="camera_left_ir_frame" />
        <child link="camera_left_ir_optical_frame" />
    </joint>
    <link name="camera_left_ir_optical_frame" />
    <!-- camera right IR joints and links -->
    <joint name="camera_right_ir_joint" type="fixed">
        <origin rpy="0 0 0" xyz="0 -0.05 0" />
        <parent link="camera_depth_frame" />
        <child link="camera_right_ir_frame" />
    </joint>
    <link name="camera_right_ir_frame" />
    <joint name="camera_right_ir_optical_joint" type="fixed">
        <origin rpy="-1.5707963267948966 0 -1.5707963267948966" xyz="0 0 0" />
        <parent link="camera_right_ir_frame" />
        <child link="camera_right_ir_optical_frame" />
    </joint>
    <link name="camera_right_ir_optical_frame" />
    <!-- camera color joints and links -->
    <joint name="camera_color_joint" type="fixed">
        <origin rpy="0 0 0" xyz="0 0.015 0" />
        <parent link="camera_depth_frame" />
        <child link="camera_color_frame" />
    </joint>
    <link name="camera_color_frame" />
    <joint name="camera_color_optical_joint" type="fixed">
        <origin rpy="-1.5707963267948966 0 -1.5707963267948966" xyz="0 0 0" />
        <parent link="camera_color_frame" />
        <child link="camera_color_optical_frame" />
    </joint>
    <link name="camera_color_optical_frame" />
    <gazebo reference="camera_link">
        <self_collide>0</self_collide>
        <enable_wind>0</enable_wind>
        <kinematic>0</kinematic>
        <gravity>1</gravity>
        <!--<mu>1</mu>-->
        <mu2>1</mu2>
        <fdir1>0 0 0</fdir1>
        <!--<slip1>0</slip1>
      <slip2>0</slip2>-->
        <kp>1e+13</kp>
        <kd>1</kd>
        <!--<max_vel>0.01</max_vel>
      <min_depth>0</min_depth>-->
        <sensor name="cameracolor" type="camera">
            <camera name="camera">
                <horizontal_fov>1.2112585008840648</horizontal_fov>
                <image>
                    <width>640</width>
                    <height>480</height>
                    <format>RGB_INT8</format>
                </image>
                <clip>
                    <near>0.1</near>
                    <far>100</far>
                </clip>
                <noise>
                    <type>gaussian</type>
                    <mean>0.0</mean>
                    <stddev>0.007</stddev>
                </noise>
            </camera>
            <always_on>1</always_on>
            <update_rate>30</update_rate>
            <visualize>1</visualize>
        </sensor>
        <sensor name="cameraired1" type="camera">
            <camera name="camera">
                <horizontal_fov>1.4870205226991688</horizontal_fov>
                <image>
                    <width>1280</width>
                    <height>720</height>
                    <format>L_INT8</format>
                </image>
                <clip>
                    <near>0.1</near>
                    <far>100</far>
                </clip>
                <noise>
                    <type>gaussian</type>
                    <mean>0.0</mean>
                    <stddev>0.05</stddev>
                </noise>
            </camera>
            <always_on>1</always_on>
            <update_rate>90</update_rate>
            <visualize>0</visualize>
        </sensor>
        <sensor name="cameraired2" type="camera">
            <camera name="camera">
                <horizontal_fov>1.4870205226991688</horizontal_fov>
                <image>
                    <width>1280</width>
                    <height>720</height>
                    <format>L_INT8</format>
                </image>
                <clip>
                    <near>0.1</near>
                    <far>100</far>
                </clip>
                <noise>
                    <type>gaussian</type>
                    <mean>0.0</mean>
                    <stddev>0.05</stddev>
                </noise>
            </camera>
            <always_on>1</always_on>
            <update_rate>90</update_rate>
            <visualize>0</visualize>
        </sensor>
        <sensor name="cameradepth" type="depth">
            <camera name="camera">
                <horizontal_fov>1.4870205226991688</horizontal_fov>
                <image>
                    <width>1280</width>
                    <height>720</height>
                </image>
                <clip>
                    <near>0.1</near>
                    <far>100</far>
                </clip>
                <noise>
                    <type>gaussian</type>
                    <mean>0.0</mean>
                    <stddev>0.100</stddev>
                </noise>
            </camera>
            <always_on>1</always_on>
            <update_rate>90</update_rate>
            <visualize>0</visualize>
        </sensor>
    </gazebo>
    <gazebo>
        <plugin filename="librealsense_gazebo_plugin.so" name="camera">
            <prefix>camera</prefix>
            <depthUpdateRate>30.0</depthUpdateRate>
            <colorUpdateRate>30.0</colorUpdateRate>
            <infraredUpdateRate>30.0</infraredUpdateRate>
            <depthTopicName>depth/image_rect_raw</depthTopicName>
            <depthCameraInfoTopicName>depth/camera_info</depthCameraInfoTopicName>
            <colorTopicName>color/image_raw</colorTopicName>
            <colorCameraInfoTopicName>color/camera_info</colorCameraInfoTopicName>
            <infrared1TopicName>infra1/image_raw</infrared1TopicName>
            <infrared1CameraInfoTopicName>infra1/camera_info</infrared1CameraInfoTopicName>
            <infrared2TopicName>infra2/image_raw</infrared2TopicName>
            <infrared2CameraInfoTopicName>infra2/camera_info</infrared2CameraInfoTopicName>
            <colorOpticalframeName>camera_color_optical_frame</colorOpticalframeName>
            <depthOpticalframeName>camera_depth_optical_frame</depthOpticalframeName>
            <infrared1OpticalframeName>camera_left_ir_optical_frame</infrared1OpticalframeName>
            <infrared2OpticalframeName>camera_right_ir_optical_frame</infrared2OpticalframeName>
            <rangeMinDepth>0.2</rangeMinDepth>
            <rangeMaxDepth>10.0</rangeMaxDepth>
            <pointCloud>True</pointCloud>
            <pointCloudTopicName>depth/color/points</pointCloudTopicName>
            <pointCloudCutoff>0.25</pointCloudCutoff>
            <pointCloudCutoffMax>9.0</pointCloudCutoffMax>
        </plugin>
    </gazebo>
    <!-- joint between base_link and arm_0_link -->
    <joint name="arm_joint_0" type="revolute">
        <origin rpy="0 0 0" xyz="0.148 0.0025 0.147" />
        <parent link="base_link" />
        <child link="arm_link_0" />
        <axis xyz="0 0 1" />
        <dynamics damping="10" friction="10" />
        <limit effort="100" lower="-3.1415" upper="3.1415" velocity="1.5707963267948966" />
    </joint>
    <link name="arm_link_0">
        <inertial>
            <!--<origin xyz="0.023 0 0.006" rpy="0 0 0"/>-->
            <origin rpy="0 0 0" xyz="0 0 0" />
            <mass value="0.01" />
            <inertia ixx="0.01" ixy="0" ixz="0" iyy="0.01" iyz="0" izz="0.01" />
        </inertial>
        <visual>
            <origin rpy="0 0 0" xyz="0 0 0" />
            <geometry>
                <mesh filename="package://talos_description/meshes/talos_arm/shoulder_link.stl" />
            </geometry>
            <material name="">
                <color rgba="0.0 0.0 0.0 1.0" />
            </material>
        </visual>
        <collision>
            <!--<origin xyz="0.023 0 0.006" rpy="0 0 0"/>-->
            <origin rpy="0 0 0" xyz="0 0 0" />
            <geometry>
                <mesh filename="package://talos_description/meshes/talos_arm/shoulder_link.stl" />
                <!--<cylinder length="0.078" radius="0.093"/>-->
            </geometry>
        </collision>
    </link>
    <!-- joint between arm_0_link and arm_1_link -->
    <joint name="arm_joint_1" type="revolute">
        <origin rpy="0 0 0" xyz="0 0 0" />
        <parent link="arm_link_0" />
        <child link="arm_link_1" />
        <axis xyz="0 1 0" />
        <!--<calibration rising="${arm_1_ref}" falling="${arm_1_ref}"/>-->
        <dynamics damping="10" friction="10" />
        <!-- damping - N*s/m, N*s*m/rad -->
        <!-- friction - N, N*m -->
        <limit effort="100" lower="-3.1415" upper="3.1415" velocity="1.5707963267948966" />
        <!--effort - N, N*m-->
        <!--velocity - m/s, rad/s-->
        <!--k_position N/m, N/rad-->
        <!--k_velocity N*s/m, N*s*m/rad-->
        <!--for details: http://www.ros.org/wiki/pr2_controller_manager/safety_limits-->
    </joint>
    <link name="arm_link_1">
        <inertial>
            <mass value="0.01" />
            <origin rpy="0 0 0" xyz="0.0482 0 0.14" />
            <inertia ixx="0.003863" ixy="-0.000979" ixz="0.000000" iyy="0.006196" iyz="0.000000" izz="0.006369" />
        </inertial>
        <visual>
            <origin rpy="0 0 0" xyz="0.0482 0 0.14" />
            <geometry>
                <mesh filename="package://talos_description/meshes/talos_arm/biceps_link.stl" />
            </geometry>
            <material name="">
                <color rgba="0.0 0.0 0.0 1.0" />
            </material>
        </visual>
        <collision>
            <!--<origin xyz="0 0 -0.003" rpy="0 0 0" />-->
            <origin rpy="0 0 0" xyz="0.0482 0 0.14" />
            <geometry>
                <mesh filename="package://talos_description/meshes/talos_arm/biceps_link.stl" />
                <!--<cylinder length="0.102" radius="0.080"/>-->
            </geometry>
        </collision>
    </link>
    <!-- joint between arm_1_link and arm_2_link -->
    <joint name="arm_joint_2" type="revolute">
        <origin rpy="0 1.5707963267948966 0" xyz="0.0482 0 0.142" />
        <parent link="arm_link_1" />
        <child link="arm_link_2" />
        <axis xyz="0 1 0" />
        <!--<calibration rising="${arm_2_ref}" falling="${arm_2_ref}"/>-->
        <dynamics damping="10" friction="10" />
        <limit effort="100" lower="-1.571" upper="1.571" velocity="1.5707963267948966" />
    </joint>
    <link name="arm_link_2">
        <inertial>
            <mass value="0.01" />
            <origin rpy="0 0 0" xyz="0 0 0.142" />
            <inertia ixx="0.000823" ixy="0.000000" ixz="-0.000000" iyy="0.004447" iyz="0.000000" izz="0.004439" />
        </inertial>
        <visual>
            <origin rpy="0 0 0" xyz="0 0 0.142" />
            <geometry>
                <mesh filename="package://talos_description/meshes/talos_arm/forearm_link.stl" />
            </geometry>
            <material name="">
                <color rgba="0.0 0.0 0.0 1.0" />
            </material>
        </visual>
        <collision>
            <!--<origin xyz="0.001 -0.041 0.074" rpy="0 0 0" />-->
            <origin rpy="0 0 0" xyz="0 0 0.142" />
            <geometry>
                <mesh filename="package://talos_description/meshes/talos_arm/forearm_link.stl" />
                <!--<box size="0.074 0.082 0.222"/>-->
            </geometry>
        </collision>
    </link>
    <!-- joint between arm_2_link and arm_3_link -->
    <joint name="arm_joint_3" type="revolute">
        <origin rpy="0 0 0" xyz="0 0 0.142" />
        <parent link="arm_link_2" />
        <child link="arm_link_3" />
        <axis xyz="0 1 0" />
        <dynamics damping="10" friction="10" />
        <limit effort="100" lower="-1.571" upper="1.571" velocity="1.5707963267948966" />
    </joint>
    <link name="arm_link_3">
        <inertial>
            <mass value="0.01" />
            <origin rpy="0 0 0" xyz="0 0 0" />
            <inertia ixx="0.002459" ixy="0.000000" ixz="0.000000" iyy="0.002571" iyz="-0.000000" izz="0.000535" />
        </inertial>
        <visual>
            <origin rpy="0 0 0" xyz="0 0 0" />
            <geometry>
                <mesh filename="package://talos_description/meshes/talos_arm/wrist_1_link.stl" />
            </geometry>
            <material name="">
                <color rgba="0.0 0.0 0.0 1.0" />
            </material>
        </visual>
        <collision>
            <!--<origin xyz="0.000 0.025 0.067" rpy="0 0 0" />-->
            <origin rpy="0 0 0" xyz="0 0 0" />
            <geometry>
                <mesh filename="package://talos_description/meshes/talos_arm/wrist_1_link.stl" />
                <!--<box size="0.064 0.054 0.192"/>-->
            </geometry>
        </collision>
    </link>
    <!-- joint between arm_3_link and arm_4_link -->
    <joint name="arm_joint_4" type="revolute">
        <origin rpy="0 0 0" xyz="0 0 0.0715" />
        <parent link="arm_link_3" />
        <child link="arm_link_4" />
        <axis xyz="0 0 1" />
        <!--<calibration rising="${arm_4_ref}" falling="${arm_4_ref}"/>-->
        <dynamics damping="10" friction="10" />
        <limit effort="100" lower="-1.571" upper="1.571" velocity="1.5707963267948966" />
    </joint>
    <link name="arm_link_4">
        <inertial>
            <mass value="0.01" />
            <origin rpy="0 0 0" xyz="0 0 0.043" />
            <inertia ixx="0.000869" ixy="0.000000" ixz="-0.000000" iyy="0.001173" iyz="-0.000231" izz="0.001091" />
        </inertial>
        <visual>
            <origin rpy="0 0 0" xyz="0 0 0.043" />
            <geometry>
                <mesh filename="package://talos_description/meshes/talos_arm/wrist_2_link.stl" />
            </geometry>
            <material name="">
                <color rgba="0.0 0.0 0.0 1.0" />
            </material>
        </visual>
        <collision>
            <!--<origin xyz="0 0 0.026" rpy="0 0 0" />-->
            <origin rpy="0 0 0" xyz="0 0 0.043" />
            <geometry>
                <mesh filename="package://talos_description/meshes/talos_arm/wrist_2_link.stl" />
                <!--<box size="0.058 0.100 0.118"/>-->
            </geometry>
        </collision>
    </link>
    <!-- joint between arm_4_link and arm_5_link -->
    <joint name="arm_joint_5" type="fixed">
        <origin rpy="0 0 0" xyz="0 0 0.043" />
        <parent link="arm_link_4" />
        <child link="arm_link_5" />
        <axis xyz="0 0 1" />
        <!--<calibration rising="${arm_4_ref}" falling="${arm_4_ref}"/>-->
        <dynamics damping="10" friction="10" />
        <limit effort="100" lower="-2.617" upper="2.617" velocity="1.5707963267948966" />
    </joint>
    <link name="arm_link_5">
        <inertial>
            <mass value="0.01" />
            <origin rpy="0 0 0" xyz="0 0 0.043" />
            <inertia ixx="0.000869" ixy="0.000000" ixz="-0.000000" iyy="0.001173" iyz="-0.000231" izz="0.001091" />
        </inertial>
        <visual>
            <origin rpy="0 0 1.57" xyz="0 0 0" />
            <geometry>
                <mesh filename="package://talos_description/meshes/talos_arm/gripper_rail_link.stl" />
            </geometry>
            <material name="">
                <color rgba="0.0 0.0 0.0 1.0" />
            </material>
        </visual>
        <collision>
            <!--<origin xyz="0 0 0.026" rpy="0 0 0" />-->
            <origin rpy="0 0 1.57" xyz="0 0 0" />
            <geometry>
                <mesh filename="package://talos_description/meshes/talos_arm/gripper_rail_link.stl" />
                <!--<box size="0.058 0.100 0.118"/>-->
            </geometry>
        </collision>
    </link>
    <!-- joint between arm_5_link and arm_6_link -->
    <joint name="arm_joint_6" type="prismatic">
        <origin rpy="0 0 0" xyz="0 0 0" />
        <parent link="arm_link_5" />
        <child link="arm_link_6" />
        <axis xyz="0 -1 0" />
        <!--<calibration rising="${arm_5_ref}" falling="${arm_5_ref}"/>-->
        <dynamics damping="10" friction="10" />
        <limit effort="100" lower="0" upper="0.024" velocity="1.5707963267948966" />
    </joint>
    <link name="arm_link_6">
        <inertial>
            <mass value="0.01" />
            <origin rpy="0 0 1.57" xyz="0 0 0" />
            <inertia ixx="0.000280" ixy="0.000000" ixz="0.000000" iyy="0.000339" iyz="0.000000" izz="0.000119" />
        </inertial>
        <visual>
            <origin rpy="0 0 1.57" xyz="0 0 0" />
            <geometry>
                <mesh filename="package://talos_description/meshes/talos_arm/gripper_hand_fixed_link.stl" />
            </geometry>
            <material name="">
                <color rgba="0.0 0.0 0.0 1.0" />
            </material>
        </visual>
        <collision>
            <origin rpy="0 0 1.57" xyz="0 0 0" />
            <geometry>
                <mesh filename="package://talos_description/meshes/talos_arm/gripper_hand_fixed_link.stl" />
                <!--<box size="0.054 0.096 0.030"/>-->
            </geometry>
        </collision>
    </link>
    <!-- joint between arm_5_link and arm_7_link -->
    <joint name="arm_joint_7" type="prismatic">
        <origin rpy="0 0 0" xyz="0 0 0" />
        <parent link="arm_link_5" />
        <child link="arm_link_7" />
        <axis xyz="0 1 0" />
        <!--<calibration rising="${arm_5_ref}" falling="${arm_5_ref}"/>-->
        <dynamics damping="10" friction="10" />
        <limit effort="100" lower="0" upper="0.024" velocity="1.5707963267948966" />
    </joint>
    <link name="arm_link_7">
        <inertial>
            <mass value="0.01" />
            <origin rpy="0 0 -1.57" xyz="0 0 0" />
            <inertia ixx="0.000280" ixy="0.000000" ixz="0.000000" iyy="0.000339" iyz="0.000000" izz="0.000119" />
        </inertial>
        <visual>
            <origin rpy="0 0 -1.57" xyz="0 0 0" />
            <geometry>
                <mesh filename="package://talos_description/meshes/talos_arm/gripper_hand_fixed_link.stl" />
            </geometry>
            <material name="">
                <color rgba="0.0 0.0 0.0 1.0" />
            </material>
        </visual>
        <collision>
            <origin rpy="0 0 -1.57" xyz="0 0 0" />
            <geometry>
                <mesh filename="package://talos_description/meshes/talos_arm/gripper_hand_fixed_link.stl" />
                <!--<box size="0.054 0.096 0.030"/>-->
            </geometry>
        </collision>
    </link>
    <gazebo reference="arm_link_0">
        <!--material value="youbot/DarkGrey" /-->
        <turnGravityOff>false</turnGravityOff>
        <dampingFactor>100000</dampingFactor>
        <kp>100000.0</kp>
        <kd>1000.0</kd>
        <mu1>1.5</mu1>
        <mu2>1.5</mu2>
        <fdir>1 0 0</fdir>
        <maxVel>1.0</maxVel>
        <minDepth>0.002</minDepth>
    </gazebo>
    <gazebo reference="arm_link_1">
        <!--<material value="youbot/Orange" />-->
        <turnGravityOff>false</turnGravityOff>
        <dampingFactor>100000</dampingFactor>
        <kp>100000.0</kp>
        <kd>1000.0</kd>
        <mu1>1.5</mu1>
        <mu2>1.5</mu2>
        <fdir>1 0 0</fdir>
        <maxVel>1.0</maxVel>
    </gazebo>
    <gazebo reference="arm_link_2">
        <!--<material value="youbot/Orange" />-->
        <turnGravityOff>false</turnGravityOff>
        <dampingFactor>100000</dampingFactor>
        <kp>100000.0</kp>
        <kd>1000.0</kd>
        <mu1>1.5</mu1>
        <mu2>1.5</mu2>
        <fdir>1 0 0</fdir>
        <maxVel>1.0</maxVel>
    </gazebo>
    <gazebo reference="arm_link_3">
        <!--<material value="youbot/Orange" />-->
        <turnGravityOff>false</turnGravityOff>
        <dampingFactor>100000</dampingFactor>
        <kp>100000.0</kp>
        <kd>1000.0</kd>
        <mu1>1.5</mu1>
        <mu2>1.5</mu2>
        <fdir>1 0 0</fdir>
        <maxVel>1.0</maxVel>
    </gazebo>
    <gazebo reference="arm_link_4">
        <!--<material value="youbot/Orange" />-->
        <turnGravityOff>false</turnGravityOff>
        <dampingFactor>100000</dampingFactor>
        <kp>100000.0</kp>
        <kd>1000.0</kd>
        <mu1>1.5</mu1>
        <mu2>1.5</mu2>
        <fdir>1 0 0</fdir>
        <maxVel>1.0</maxVel>
    </gazebo>
    <gazebo reference="arm_link_5">
        <!--<material value="youbot/DarkGrey" />-->
        <turnGravityOff>false</turnGravityOff>
        <dampingFactor>100000</dampingFactor>
        <kp>100000.0</kp>
        <kd>1000.0</kd>
        <mu1>1.5</mu1>
        <mu2>1.5</mu2>
        <fdir>1 0 0</fdir>
        <maxVel>1.0</maxVel>
    </gazebo>
    <gazebo reference="arm_link_6">
        <!--<material value="youbot/DarkGrey" />-->
        <turnGravityOff>false</turnGravityOff>
        <dampingFactor>100000</dampingFactor>
        <kp>100000.0</kp>
        <kd>1000.0</kd>
        <mu1>1.5</mu1>
        <mu2>1.5</mu2>
        <fdir>1 0 0</fdir>
        <maxVel>1.0</maxVel>
    </gazebo>
    <gazebo reference="arm_link_7">
        <!--<material value="youbot/DarkGrey" />-->
        <turnGravityOff>false</turnGravityOff>
        <dampingFactor>100000</dampingFactor>
        <kp>100000.0</kp>
        <kd>1000.0</kd>
        <mu1>1.5</mu1>
        <mu2>1.5</mu2>
        <fdir>1 0 0</fdir>
        <maxVel>1.0</maxVel>
    </gazebo>
    <transmission name="arm_trans_0">
        <type>transmission_interface/SimpleTransmission</type>
        <joint name="arm_joint_0">
            <hardwareInterface>hardware_interface/EffortJointInterface</hardwareInterface>
        </joint>
        <actuator name="arm_joint_0_actr">
            <hardwareInterface>hardware_interface/EffortJointInterface</hardwareInterface>
            <mechanicalReduction>1</mechanicalReduction>
        </actuator>
    </transmission>
    <transmission name="arm_trans_1">
        <type>transmission_interface/SimpleTransmission</type>
        <joint name="arm_joint_1">
            <hardwareInterface>hardware_interface/EffortJointInterface</hardwareInterface>
        </joint>
        <actuator name="arm_joint_1_actr">
            <hardwareInterface>hardware_interface/EffortJointInterface</hardwareInterface>
            <mechanicalReduction>1</mechanicalReduction>
        </actuator>
    </transmission>
    <transmission name="arm_trans_2">
        <type>transmission_interface/SimpleTransmission</type>
        <joint name="arm_joint_2">
            <hardwareInterface>hardware_interface/EffortJointInterface</hardwareInterface>
        </joint>
        <actuator name="arm_joint_2_actr">
            <hardwareInterface>hardware_interface/EffortJointInterface</hardwareInterface>
            <mechanicalReduction>1</mechanicalReduction>
        </actuator>
    </transmission>
    <transmission name="arm_trans_3">
        <type>transmission_interface/SimpleTransmission</type>
        <joint name="arm_joint_3">
            <hardwareInterface>hardware_interface/EffortJointInterface</hardwareInterface>
        </joint>
        <actuator name="arm_joint_3_actr">
            <hardwareInterface>hardware_interface/EffortJointInterface</hardwareInterface>
            <mechanicalReduction>1</mechanicalReduction>
        </actuator>
    </transmission>
    <transmission name="arm_trans_4">
        <type>transmission_interface/SimpleTransmission</type>
        <joint name="arm_joint_4">
            <hardwareInterface>hardware_interface/EffortJointInterface</hardwareInterface>
        </joint>
        <actuator name="arm_joint_4_actr">
            <hardwareInterface>hardware_interface/EffortJointInterface</hardwareInterface>
            <mechanicalReduction>1</mechanicalReduction>
        </actuator>
    </transmission>
    <transmission name="arm_trans_6">
        <type>transmission_interface/SimpleTransmission</type>
        <joint name="arm_joint_6">
            <hardwareInterface>hardware_interface/EffortJointInterface</hardwareInterface>
        </joint>
        <actuator name="arm_joint_6_actr">
            <hardwareInterface>hardware_interface/EffortJointInterface</hardwareInterface>
            <mechanicalReduction>1</mechanicalReduction>
        </actuator>
    </transmission>
    <transmission name="arm_trans_7">
        <type>transmission_interface/SimpleTransmission</type>
        <joint name="arm_joint_7">
            <hardwareInterface>hardware_interface/EffortJointInterface</hardwareInterface>
        </joint>
        <actuator name="arm_joint_7_actr">
            <hardwareInterface>hardware_interface/EffortJointInterface</hardwareInterface>
            <mechanicalReduction>1</mechanicalReduction>
        </actuator>
    </transmission>
</robot>

